INFO  | File run_exp_local.py     | Line 15    | Writing log file to ./exp\GTS_1_0110_043304\log_exp_1010.txt
INFO  | File run_exp_local.py     | Line 16    | Exp instance id = GTS_1_0110_043304
ERROR | File run_exp_local.py     | Line 25    | Traceback (most recent call last):
  File "C:\Users\KimJuHyeon\GSL\run_exp_local.py", line 19, in main
    runner = GTS_Runner(config=config)
  File "C:\Users\KimJuHyeon\GSL\runner\GTS_runner.py", line 84, in __init__
    self.graph_forecasting = GTS_Forecasting_Module(self.config)
  File "C:\Users\KimJuHyeon\GSL\models\GTS\gts_forecasting_module.py", line 104, in __init__
    self.embedding = Embedding(config)
  File "C:\Users\KimJuHyeon\GSL\models\GTS\gts_forecasting_module.py", line 20, in __init__
    self.fc_dim = config.forecasting_module.embedding.fc_dim
AttributeError: 'EasyDict' object has no attribute 'fc_dim'

