INFO  | File run_exp_local.py     | Line 16    | Writing log file to ./exp/GTS_1_0310_124137/log_exp_1010.txt
INFO  | File run_exp_local.py     | Line 17    | Exp instance id = GTS_1_0310_124137
ERROR | File run_exp_local.py     | Line 25    | Traceback (most recent call last):
  File "/Users/juhyeonkim/Dropbox/내 Mac (JuHyeonui-iMac.local)/Documents/GraphStructureLearning/run_exp_local.py", line 21, in main
    runner.train()
  File "/Users/juhyeonkim/Dropbox/내 Mac (JuHyeonui-iMac.local)/Documents/GraphStructureLearning/runner/GTS_runner.py", line 109, in train
    _, outputs = self.model(data_batch.x, data_batch.y, self.entire_inputs, self.init_edge_index)
  File "/opt/anaconda3/envs/GSL/lib/python3.8/site-packages/torch/nn/modules/module.py", line 1102, in _call_impl
    return forward_call(*input, **kwargs)
  File "/Users/juhyeonkim/Dropbox/내 Mac (JuHyeonui-iMac.local)/Documents/GraphStructureLearning/models/GTS/GTS_model.py", line 94, in forward
    batch_adj_matrix, batch_weight_matrix, adj_matrix = self._weight_matrix_construct(adj, edge_index,
  File "/Users/juhyeonkim/Dropbox/내 Mac (JuHyeonui-iMac.local)/Documents/GraphStructureLearning/models/GTS/GTS_model.py", line 77, in _weight_matrix_construct
    init_edge_index, adj = init_edge_index(adj)
TypeError: 'Tensor' object is not callable

